Workbook

Sheet Control
A1: Platforms | D1: Fantasy Pros | E1: ESPN | F1: NFL.com | J1: ESPN_Excel_Bridge_FINAL_STABLE_v2.1_TEAM\ESPN_Excel_Bridge_FINAL_STABLE_v2.1_TEAM\Start ESPN Excel Bridge.bat
A2: ESPN | D2: Ja'Marr Chase | E2: Ja'Marr Chase | F2: Ja'Marr Chase
A3: Yahoo | D3: Bijan Robinson | E3: Bijan Robinson | F3: Bijan Robinson
A4: NFL.com | D4: Saquon Barkley | E4: Saquon Barkley | F4: Saquon Barkley
A5: Sleeper | D5: Justin Jefferson | E5: Justin Jefferson | F5: Justin Jefferson
D6: CeeDee Lamb | E6: CeeDee Lamb | F6: CeeDee Lamb
D7: Jahmyr Gibbs | E7: Jahmyr Gibbs | F7: Jahmyr Gibbs
D8: Derrick Henry | E8: Derrick Henry | F8: Derrick Henry
D9: Nico Collins | E9: Nico Collins | F9: Nico Collins
D10: Puka Nacua | E10: Puka Nacua | F10: Puka Nacua
D11: Malik Nabers | E11: Malik Nabers | F11: Malik Nabers
D12: Brian Thomas Jr. | E12: Brian Thomas Jr. | F12: Brian Thomas Jr.
D13: Amon-Ra St. Brown | E13: Amon-Ra St. Brown | F13: Amon-Ra St. Brown
D14: Christian McCaffrey | E14: Christian McCaffrey | F14: Christian McCaffrey
D15: Ashton Jeanty | E15: Ashton Jeanty | F15: Ashton Jeanty
D16: A.J. Brown | E16: A.J. Brown | F16: A.J. Brown
D17: Jonathan Taylor | E17: Jonathan Taylor | F17: Jonathan Taylor
... D108: Zach Charbonnet | E108: Zach Charbonnet | F108: Zach Charbonnet
D109: J.K. Dobbins | E109: J.K. Dobbins
D110: Emeka Egbuka | E110: Emeka Egbuka | F110: Emeka Egbuka
D111: Khalil Shakir | E111: Khalil Shakir | F111: Khalil Shakir
D112: Jordan Love | E112: Jordan Love | F112: Jordan Love
D113: Matthew Golden | E113: Matthew Golden | F113: Matthew Golden
D114: Najee Harris | E114: Najee Harris | F114: Najee Harris
D115: Cam Skattebo | E115: Cam Skattebo | F115: Cam Skattebo
D116: Josh Downs | E116: Josh Downs | F116: Josh Downs
D117: Trevor Lawrence | E117: Trevor Lawrence | F117: Trevor Lawrence
D118: C.J. Stroud | E118: C.J. Stroud | F118: C.J. Stroud
D119: Dalton Kincaid | E119: Dalton Kincaid | F119: Dalton Kincaid
D120: Quinshon Judkins | E120: Quinshon Judkins | F120: Quinshon Judkins
D121: Cooper Kupp | E121: Cooper Kupp | F121: Cooper Kupp
... D144: Christian Kirk | E144: Christian Kirk | F144: Christian Kirk
D145: Jerome Ford | E145: Jerome Ford
D146: Nick Chubb | E146: Nick Chubb
D147: Marvin Mims Jr. | E147: Marvin Mims Jr. | F147: Marvin Mims Jr.
D148: Hunter Henry | E148: Hunter Henry | F148: Hunter Henry
D149: Luther Burden III | E149: Luther Burden III | F149: Luther Burden III
D150: Jonnu Smith | E150: Jonnu Smith | F150: Jonnu Smith
D151: Michael Penix Jr. | E151: Michael Penix Jr. | F151: Michael Penix Jr.
D152: Rico Dowdle | E152: Rico Dowdle | F152: Rico Dowdle
...

Sheet ESPN Rankings
A1: Overall Rank | B1: Pos Rank | C1: Position | D1: Player | E1: Team | F1: Mapped Name
A2: 1 | B2: RB1 | C2: RB | D2: Jahmyr Gibbs | E2: DET | F2: =INDEX(Table5[Fantasy Pros],MATCH(Table2[[#This Row],[Player]],Table5[ESPN],0)) -> Jahmyr Gibbs
A3: 2 | B3: RB2 | C3: RB | D3: Bijan Robinson | E3: ATL | F3: =INDEX(Table5[Fantasy Pros],MATCH(Table2[[#This Row],[Player]],Table5[ESPN],0)) -> Bijan Robinson
A4: 3 | B4: WR1 | C4: WR | D4: Ja'Marr Chase | E4: CIN | F4: =INDEX(Table5[Fantasy Pros],MATCH(Table2[[#This Row],[Player]],Table5[ESPN],0)) -> Ja'Marr Chase
A5: 4 | B5: WR2 | C5: WR | D5: Puka Nacua | E5: LAR | F5: =INDEX(Table5[Fantasy Pros],MATCH(Table2[[#This Row],[Player]],Table5[ESPN],0)) -> Puka Nacua
A6: 5 | B6: WR3 | C6: WR | D6: Jaxon Smith-Njigba | E6: SEA | F6: =INDEX(Table5[Fantasy Pros],MATCH(Table2[[#This Row],[Player]],Table5[ESPN],0)) -> Jaxon Smith-Njigba
A7: 6 | B7: RB3 | C7: RB | D7: Christian McCaffrey | E7: SF | F7: =INDEX(Table5[Fantasy Pros],MATCH(Table2[[#This Row],[Player]],Table5[ESPN],0)) -> Christian McCaffrey
A8: 7 | B8: RB4 | C8: RB | D8: Jonathan Taylor | E8: IND | F8: =INDEX(Table5[Fantasy Pros],MATCH(Table2[[#This Row],[Player]],Table5[ESPN],0)) -> Jonathan Taylor
A9: 8 | B9: WR4 | C9: WR | D9: Amon-Ra St. Brown | E9: DET | F9: =INDEX(Table5[Fantasy Pros],MATCH(Table2[[#This Row],[Player]],Table5[ESPN],0)) -> Amon-Ra St. Brown
A10: 9 | B10: WR5 | C10: WR | D10: CeeDee Lamb | E10: DAL | F10: =INDEX(Table5[Fantasy Pros],MATCH(Table2[[#This Row],[Player]],Table5[ESPN],0)) -> CeeDee Lamb
A11: 10 | B11: WR6 | C11: WR | D11: Justin Jefferson | E11: MIN | F11: =INDEX(Table5[Fantasy Pros],MATCH(Table2[[#This Row],[Player]],Table5[ESPN],0)) -> Justin Jefferson
A12: 11 | B12: RB5 | C12: RB | D12: Derrick Henry | E12: BAL | F12: =INDEX(Table5[Fantasy Pros],MATCH(Table2[[#This Row],[Player]],Table5[ESPN],0)) -> Derrick Henry
A13: 12 | B13: RB6 | C13: RB | D13: James Cook III | E13: BUF | F13: =INDEX(Table5[Fantasy Pros],MATCH(Table2[[#This Row],[Player]],Table5[ESPN],0)) -> James Cook III
... A301: 300 | B301: DST22 | C301: DST | D301: Bengals D/ST | E301: CIN | F301: =INDEX(Table5[Fantasy Pros],MATCH(Table2[[#This Row],[Player]],Table5[ESPN],0)) -> Cincinnati

Sheet Fantasy Pros Standard Rankings
A1: RK | B1: PLAYER NAME | C1: TEAM | D1: POS | E1: BYE WEEK | F1: SOS SEASON | G1: ECR VS. ADP
A2: 1 | B2: Jahmyr Gibbs | C2: DET | D2: RB1 | E2: 6 | F2: 5 out of 5 stars | G2: 0
A3: 2 | B3: Ja'Marr Chase | C3: CIN | D3: WR1 | E3: 6 | F3: 4 out of 5 stars | G3: 1
A4: 3 | B4: Bijan Robinson | C4: ATL | D4: RB2 | E4: 11 | F4: 2 out of 5 stars | G4: -1
A5: 4 | B5: Puka Nacua | C5: LAR | D5: WR2 | E5: 11 | F5: 1 out of 5 stars | G5: 2
A6: 5 | B6: Jaxon Smith-Njigba | C6: SEA | D6: WR3 | E6: 11 | F6: 3 out of 5 stars | G6: 3
A7: 6 | B7: Amon-Ra St. Brown | C7: DET | D7: WR4 | E7: 6 | F7: 4 out of 5 stars | G7: 6
A8: 7 | B8: Jonathan Taylor | C8: IND | D8: RB3 | E8: 13 | F8: 4 out of 5 stars | G8: -2
A9: 8 | B9: James Cook III | C9: BUF | D9: RB4 | E9: 7 | F9: 2 out of 5 stars | G9: -1
A10: 9 | B10: Christian McCaffrey | C10: SF | D10: RB5 | E10: 8 | F10: 2 out of 5 stars | G10: -5
A11: 10 | B11: CeeDee Lamb | C11: DAL | D11: WR5 | E11: 14 | F11: 2 out of 5 stars | G11: 5
A12: 11 | B12: Justin Jefferson | C12: MIN | D12: WR6 | E12: 6 | F12: 5 out of 5 stars | G12: 6
A13: 12 | B13: A.J. Brown | C13: NE | D13: WR7 | E13: 11 | F13: 2 out of 5 stars | G13: 13
... A264: 261 | B264: Cyrus Allen | C264: KC | D264: WR93 | E264: 5 | F264: 2 out of 5 stars | G264: -9
A265: 262 | B265: Tyquan Thornton | C265: KC | D265: WR94 | E265: 5 | F265: 2 out of 5 stars | G265: -
A266: 263 | B266: Colby Parkinson | C266: LAR | D266: TE32 | E266: 11 | F266: 4 out of 5 stars | G266: -86
A267: 264 | B267: Jordan James | C267: SF | D267: RB78 | E267: 8 | F267: 2 out of 5 stars | G267: 28
A268: 265 | B268: Chimere Dike | C268: TEN | D268: WR95 | E268: 9 | F268: 3 out of 5 stars | G268: -5
A269: 266 | B269: Kendre Miller | C269: NO | D269: RB79 | E269: 8 | F269: 3 out of 5 stars | G269: 6
A270: 267 | B270: Isaiah Davis | C270: NYJ | D270: RB80 | E270: 13 | F270: 3 out of 5 stars | G270: -
A271: 268 | B271: Jack Bech | C271: LV | D271: WR96 | E271: 13 | F271: 2 out of 5 stars | G271: 23
A272: 269 | B272: Tory Horton | C272: SEA | D272: WR97 | E272: 11 | F272: 3 out of 5 stars | G272: 20
A273: 270 | B273: Ty Johnson | C273: BUF | D273: RB81 | E273: 7 | F273: 2 out of 5 stars | G273: 14
A274: 271 | B274: Wil Lutz | C274: DEN | D274: K16 | E274: 10 | F274: 1 out of 5 stars | G274: -28
A275: 272 | B275: Fernando Mendoza | C275: LV | D275: QB30 | E275: 13 | F275: 1 out of 5 stars | G275: -70
A276: 273 | B276: Will Reichard | C276: MIN | D276: K17 | E276: 6 | F276: 2 out of 5 stars | G276: -37
A277: 274 | B277: Elijah Sarratt | C277: BAL | D277: WR98 | E277: 13 | F277: 4 out of 5 stars | G277: 20
A278: 275 | B278: Darius Slayton | C278: NYG | D278: WR99 | E278: 8 | F278: 4 out of 5 stars | G278: -
A279: 276 | B279: Theo Johnson | C279: NYG | D279: TE33 | E279: 8 | F279: 3 out of 5 stars | G279: -48
A280: 277 | B280: Xavier Legette | C280: CAR | D280: WR100 | E280: 5 | F280: 2 out of 5 stars | G280: -
A281: 278 | B281: Marvin Mims Jr. | C281: DEN | D281: WR101 | E281: 10 | F281: 2 out of 5 stars | G281: 5
A282: 279 | B282: Mason Taylor | C282: NYJ | D282: TE34 | E282: 13 | F282: 4 out of 5 stars | G282: -59
A283: 280 | B283: DJ Giddens | C283: IND | D283: RB82 | E283: 13 | F283: 4 out of 5 stars | G283: -
A284: 281 | B284: LeQuint Allen Jr. | C284: JAC | D284: RB83 | E284: 7 | F284: 4 out of 5 stars | G284: -
A285: 282 | B285: Kyle Williams | C285: NE | D285: WR102 | E285: 11 | F285: 2 out of 5 stars | G285: 3
A286: 283 | B286: Tua Tagovailoa | C286: ATL | D286: QB31 | E286: 11 | F286: 4 out of 5 stars | G286: -44
A287: 284 | B287: Christian Kirk | C287: SF | D287: WR103 | E287: 8 | F287: 2 out of 5 stars | G287: 21
A288: 285 | B288: Michael Penix Jr. | C288: ATL | D288: QB32 | E288: 11 | F288: 4 out of 5 stars | G288: -59
A289: 286 | B289: San Francisco 49ers | C289: SF | D289: DST17 | E289: 8 | F289: 3 out of 5 stars | G289: 16
A290: 287 | B290: Eli Stowers | C290: PHI | D290: TE35 | E290: 10 | F290: 4 out of 5 stars | G290: -65
...

Sheet DraftKings Player Summary
A1: 2026 NFL DraftKings Season-Long Player Lines — Summary
A2: *Total TD Reference is NOT a sportsbook market. It is the arithmetic sum of any available Passing TD, Rushing TD, and Receiving TD O/U lines in this workbook. Actual book TD markets are on the Touchdowns sheet.
A4: Player | B4: Pos | C4: Team | D4: Passing Yds | E4: Rushing Yds | F4: Receiving Yds | G4: Passing TDs | H4: Rushing TDs | I4: Receiving TDs | J4: Total TD Reference* | K4: TD Markets Found
A5: AJ Brown | B5: WR | C5: NE | D5: N/A | E5: N/A | F5: 1124.5 | G5: N/A | H5: N/A | I5: 7.5 | J5: =IF(COUNT(G5:I5)=0,"",SUM(G5:I5)) -> 7.5 | K5: =COUNT(G5:I5) -> 1
A6: Aaron Jones | B6: RB | C6: MIN | D6: N/A | E6: 474.5 | F6: N/A | G6: N/A | H6: N/A | I6: N/A | J6: =IF(COUNT(G6:I6)=0,"",SUM(G6:I6)) | K6: =COUNT(G6:I6) -> 0
A7: Aaron Rodgers | B7: QB | C7: PIT | D7: 3099.5 | E7: N/A | F7: N/A | G7: 21.5 | H7: N/A | I7: N/A | J7: =IF(COUNT(G7:I7)=0,"",SUM(G7:I7)) -> 21.5 | K7: =COUNT(G7:I7) -> 1
A8: Alec Pierce | B8: WR | C8: IND | D8: N/A | E8: N/A | F8: 899.5 | G8: N/A | H8: N/A | I8: N/A | J8: =IF(COUNT(G8:I8)=0,"",SUM(G8:I8)) | K8: =COUNT(G8:I8) -> 0
A9: Amon-Ra St Brown | B9: WR | C9: DET | D9: N/A | E9: N/A | F9: 1249.5 | G9: N/A | H9: N/A | I9: 9.5 | J9: =IF(COUNT(G9:I9)=0,"",SUM(G9:I9)) -> 9.5 | K9: =COUNT(G9:I9) -> 1
A10: Ashton Jeanty | B10: RB | C10: LVR | D10: N/A | E10: 1024.5 | F10: N/A | G10: N/A | H10: 7.5 | I10: N/A | J10: =IF(COUNT(G10:I10)=0,"",SUM(G10:I10)) -> 7.5 | K10: =COUNT(G10:I10) -> 1
A11: Baker Mayfield | B11: QB | C11: TB | D11: 3599.5 | E11: N/A | F11: N/A | G11: 25.5 | H11: N/A | I11: N/A | J11: =IF(COUNT(G11:I11)=0,"",SUM(G11:I11)) -> 25.5 | K11: =COUNT(G11:I11) -> 1
A12: Bhayshul Tuten | B12: RB | C12: JAX | D12: N/A | E12: 724.5 | F12: N/A | G12: N/A | H12: 5.5 | I12: N/A | J12: =IF(COUNT(G12:I12)=0,"",SUM(G12:I12)) -> 5.5 | K12: =COUNT(G12:I12) -> 1
A13: Bijan Robinson | B13: RB | C13: ATL | D13: N/A | E13: 1174.5 | F13: 574.5 | G13: N/A | H13: 8.5 | I13: 3.5 | J13: =IF(COUNT(G13:I13)=0,"",SUM(G13:I13)) -> 12 | K13: =COUNT(G13:I13) -> 2
A14: Blake Corum | B14: RB | C14: LAR | D14: N/A | E14: 699.5 | F14: N/A | G14: N/A | H14: 5.5 | I14: N/A | J14: =IF(COUNT(G14:I14)=0,"",SUM(G14:I14)) -> 5.5 | K14: =COUNT(G14:I14) -> 1
A15: Bo Nix | B15: QB | C15: DEN | D15: 3499.5 | E15: N/A | F15: N/A | G15: 24.5 | H15: N/A | I15: N/A | J15: =IF(COUNT(G15:I15)=0,"",SUM(G15:I15)) -> 24.5 | K15: =COUNT(G15:I15) -> 1
A16: Breece Hall | B16: RB | C16: NYJ | D16: N/A | E16: 899.5 | F16: N/A | G16: N/A | H16: N/A | I16: N/A | J16: =IF(COUNT(G16:I16)=0,"",SUM(G16:I16)) | K16: =COUNT(G16:I16) -> 0
A17: Brian Thomas | B17: WR | C17: JAX | D17: N/A | E17: N/A | F17: 724.5 | G17: N/A | H17: N/A | I17: 4.5 | J17: =IF(COUNT(G17:I17)=0,"",SUM(G17:I17)) -> 4.5 | K17: =COUNT(G17:I17) -> 1
A18: Brock Bowers | B18: TE | C18: LVR | D18: N/A | E18: N/A | F18: 949.5 | G18: N/A | H18: N/A | I18: 7.5 | J18: =IF(COUNT(G18:I18)=0,"",SUM(G18:I18)) -> 7.5 | K18: =COUNT(G18:I18) -> 1
A19: Brock Purdy | B19: QB | C19: SF | D19: 3799.5 | E19: N/A | F19: N/A | G19: 27.5 | H19: N/A | I19: N/A | J19: =IF(COUNT(G19:I19)=0,"",SUM(G19:I19)) -> 27.5 | K19: =COUNT(G19:I19) -> 1
A20: Bryce Young | B20: QB | C20: CAR | D20: 2874.5 | E20: N/A | F20: N/A | G20: 20.5 | H20: N/A | I20: N/A | J20: =IF(COUNT(G20:I20)=0,"",SUM(G20:I20)) -> 20.5 | K20: =COUNT(G20:I20) -> 1
A21: Bucky Irving | B21: RB | C21: TB | D21: N/A | E21: 799.5 | F21: N/A | G21: N/A | H21: 4.5 | I21: N/A | J21: =IF(COUNT(G21:I21)=0,"",SUM(G21:I21)) -> 4.5 | K21: =COUNT(G21:I21) -> 1
A22: CJ Stroud | B22: QB | C22: HOU | D22: 3549.5 | E22: N/A | F22: N/A | G22: 22.5 | H22: N/A | I22: N/A | J22: =IF(COUNT(G22:I22)=0,"",SUM(G22:I22)) -> 22.5 | K22: =COUNT(G22:I22) -> 1
A23: Caleb Williams | B23: QB | C23: CHI | D23: 3649.5 | E23: N/A | F23: N/A | G23: 24.5 | H23: N/A | I23: N/A | J23: =IF(COUNT(G23:I23)=0,"",SUM(G23:I23)) -> 24.5 | K23: =COUNT(G23:I23) -> 1
A24: Cam Ward | B24: QB | C24: TEN | D24: 3249.5 | E24: N/A | F24: N/A | G24: 20.5 | H24: N/A | I24: N/A | J24: =IF(COUNT(G24:I24)=0,"",SUM(G24:I24)) -> 20.5 | K24: =COUNT(G24:I24) -> 1
A25: Carnell Tate | B25: WR | C25: TEN | D25: N/A | E25: N/A | F25: 774.5 | G25: N/A | H25: N/A | I25: 4.5 | J25: =IF(COUNT(G25:I25)=0,"",SUM(G25:I25)) -> 4.5 | K25: =COUNT(G25:I25) -> 1
A26: Ceedee Lamb | B26: WR | C26: DAL | D26: N/A | E26: N/A | F26: 1199.5 | G26: N/A | H26: N/A | I26: 7.5 | J26: =IF(COUNT(G26:I26)=0,"",SUM(G26:I26)) -> 7.5 | K26: =COUNT(G26:I26) -> 1
A27: Chase Brown | B27: RB | C27: CIN | D27: N/A | E27: 849.5 | F27: N/A | G27: N/A | H27: 6.5 | I27: N/A | J27: =IF(COUNT(G27:I27)=0,"",SUM(G27:I27)) -> 6.5 | K27: =COUNT(G27:I27) -> 1
A28: Chris Olave | B28: WR | C28: NO | D28: N/A | E28: N/A | F28: 1049.5 | G28: N/A | H28: N/A | I28: 5.5 | J28: =IF(COUNT(G28:I28)=0,"",SUM(G28:I28)) -> 5.5 | K28: =COUNT(G28:I28) -> 1
A29: Christian McCaffrey | B29: RB | C29: SF | D29: N/A | E29: 949.5 | F29: 574.5 | G29: N/A | H29: 8.5 | I29: 4.5 | J29: =IF(COUNT(G29:I29)=0,"",SUM(G29:I29)) -> 13 | K29: =COUNT(G29:I29) -> 2
A30: Christian Watson | B30: WR | C30: GB | D30: N/A | E30: N/A | F30: 799.5 | G30: N/A | H30: N/A | I30: 6.5 | J30: =IF(COUNT(G30:I30)=0,"",SUM(G30:I30)) -> 6.5 | K30: =COUNT(G30:I30) -> 1
A31: Colston Loveland | B31: TE | C31: CHI | D31: N/A | E31: N/A | F31: 824.5 | G31: N/A | H31: N/A | I31: 5.5 | J31: =IF(COUNT(G31:I31)=0,"",SUM(G31:I31)) -> 5.5 | K31: =COUNT(G31:I31) -> 1
A32: Courtland Sutton | B32: WR | C32: DEN | D32: N/A | E32: N/A | F32: 699.5 | G32: N/A | H32: N/A | I32: 6.5 | J32: =IF(COUNT(G32:I32)=0,"",SUM(G32:I32)) -> 6.5 | K32: =COUNT(G32:I32) -> 1
A33: D'Andre Swift | B33: RB | C33: CHI | D33: N/A | E33: 824.5 | F33: N/A | G33: N/A | H33: 7.5 | I33: N/A | J33: =IF(COUNT(G33:I33)=0,"",SUM(G33:I33)) -> 7.5 | K33: =COUNT(G33:I33) -> 1
A34: DJ Moore | B34: WR | C34: BUF | D34: N/A | E34: N/A | F34: 849.5 | G34: N/A | H34: N/A | I34: 6.5 | J34: =IF(COUNT(G34:I34)=0,"",SUM(G34:I34)) -> 6.5 | K34: =COUNT(G34:I34) -> 1
A35: DK Metcalf | B35: WR | C35: PIT | D35: N/A | E35: N/A | F35: 824.5 | G35: N/A | H35: N/A | I35: 5.5 | J35: =IF(COUNT(G35:I35)=0,"",SUM(G35:I35)) -> 5.5 | K35: =COUNT(G35:I35) -> 1
A36: Dak Prescott | B36: QB | C36: DAL | D36: 3999.5 | E36: N/A | F36: N/A | G36: 27.5 | H36: N/A | I36: N/A | J36: =IF(COUNT(G36:I36)=0,"",SUM(G36:I36)) -> 27.5 | K36: =COUNT(G36:I36) -> 1
A37: Dallas Goedert | B37: TE | C37: PHI | D37: N/A | E37: N/A | F37: 574.5 | G37: N/A | H37: N/A | I37: 4.5 | J37: =IF(COUNT(G37:I37)=0,"",SUM(G37:I37)) -> 4.5 | K37: =COUNT(G37:I37) -> 1
A38: Dalton Kincaid | B38: TE | C38: BUF | D38: N/A | E38: N/A | F38: 599.5 | G38: N/A | H38: N/A | I38: 4.5 | J38: =IF(COUNT(G38:I38)=0,"",SUM(G38:I38)) -> 4.5 | K38: =COUNT(G38:I38) -> 1
A39: Daniel Jones | B39: QB | C39: IND | D39: 3299.5 | E39: N/A | F39: N/A | G39: 19.5 | H39: N/A | I39: N/A | J39: =IF(COUNT(G39:I39)=0,"",SUM(G39:I39)) -> 19.5 | K39: =COUNT(G39:I39) -> 1
A40: Davante Adams | B40: WR | C40: LAR | D40: N/A | E40: N/A | F40: 774.5 | G40: N/A | H40: N/A | I40: 9.5 | J40: =IF(COUNT(G40:I40)=0,"",SUM(G40:I40)) -> 9.5 | K40: =COUNT(G40:I40) -> 1
A41: David Montgomery | B41: RB | C41: HOU | D41: N/A | E41: 824.5 | F41: N/A | G41: N/A | H41: 7.5 | I41: N/A | J41: =IF(COUNT(G41:I41)=0,"",SUM(G41:I41)) -> 7.5 | K41: =COUNT(G41:I41) -> 1
...

Sheet Draft Log
B1: Player | C1: Drafted By | D1: Timestamp | F1: How this works | I1: ESPN Bridge | J1: Status
A2: 1 | B2: Jahmyr Gibbs | C2: Team Afeef | D2: 0.72924769 | F2: 1 | G2: Automatic ESPN feed will write each pick into columns A:D. | I2: Connection | J2: Connected ✓ — PICKS TICKER v2.4
A3: 2 | B3: Bijan Robinson | C3: Benjamins Bandits | D3: 0.72930556 | F3: 2 | G3: Your Rankings Master will instantly mark that player DRAFTED. | I3: Last Pick | J3: #170 Vikings D/ST
A4: 3 | B4: Ja'Marr Chase | C4: dontsaynosayYA | D4: 0.7297338 | F4: 3 | G4: Until ESPN is connected, you can type a player name in column B to test/use manually. | I4: League | J4: 887910102
A5: 4 | B5: Puka Nacua | C5: Cut to the Chase | D5: 0.72997685 | F5: 4 | G5: Do not edit the Drafted? formulas on Rankings Master. | I5: Season | J5: 2026
A6: 5 | B6: Jaxon Smith-Njigba | C6: JJetts Skatt Hurts | D6: 0.73096065
A7: 6 | B7: Amon-Ra St. Brown | C7: BEST COUNTRY IN THE WORLD | D7: 0.73189815
A8: 7 | B8: Jonathan Taylor | C8: Eight Bell Tolls | D8: 0.73197917
A9: 8 | B9: James Cook III | C9: Mustafa is Not Like Us | D9: 0.73224537
A10: 9 | B10: CeeDee Lamb | C10: The Good, Bad and Ugly | D10: 0.73230324
A11: 10 | B11: Christian McCaffrey | C11: Double Chubb Chocolate Cookie | D11: 0.73240741
A12: 11 | B12: Justin Jefferson | C12: Double Chubb Chocolate Cookie | D12: 0.73253472
A13: 12 | B13: Derrick Henry | C13: The Good, Bad and Ugly | D13: 0.73280093
A14: 13 | B14: Omarion Hampton | C14: Mustafa is Not Like Us | D14: 0.7337037
A15: 14 | B15: De'Von Achane | C15: Eight Bell Tolls | D15: 0.73424769
A16: 15 | B16: Saquon Barkley | C16: BEST COUNTRY IN THE WORLD | D16: 0.73443287
A17: 16 | B17: Trey McBride | C17: JJetts Skatt Hurts | D17: 0.73543981
... A171: 170 | B171: Vikings D/ST | C171: Double Chubb Chocolate Cookie | D171: 0.79885417

Sheet Rankings Master
A1: Platform | D1: ESPN | F1: Team Name: | G1: Mustafa is Not Like Us
A3: Rank | B3: Player | C3: Last | D3: Name | E3: Position | F3: Fantasy Pros Rank | G3: Difference | H3: % Difference | I3: Rating | J3: Picked? | K3: Position | L3: Code | M3: Rushing Yards Prop | N3: Receiving Yards Prop | O3: Passing Yards Prop | Q3: Code | R3: Team | S3: Player | U3: Drafted? | V3: Pick # | W3: Drafted By | Z3: Team | AA3: QB | AB3: RB | AC3: WR | AD3: TE
A4: 1 | B4: Christian | C4: McCaffrey | D4: =IF($D$1="ESPN",INDEX(Table2[Mapped Name],MATCH('Rankings Master'!$A4,Table2[Overall Rank],0)),IF('Rankings Master'!$D$1="NFL.com",INDEX(Table3[Name Clean],MATCH('Rankings Master'!$A4,Table3[Rank],0)),IF('Rankings Master'!$D$1="Sleeper",INDEX(Sleeper!$B$2:$B$201,MATCH('Rankings Master'!$A4,Sleeper!$A$2:$A$201,0)),"Need platform"))) -> Jahmyr Gibbs | E4: =IF($D$1="ESPN",INDEX(Table2[Position],MATCH('Rankings Master'!$A4,Table2[Overall Rank],0)),IF('Rankings Master'!$D$1="NFL.com",INDEX(Table3[Position],MATCH('Rankings Master'!$A4,Table3[Rank],0)),INDEX(Sleeper!$C$2:$C$201,MATCH('Rankings Master'!A4,Sleeper!$A$2:$A$201,0)))) -> RB | F4: =INDEX(Table4[RK],MATCH('Rankings Master'!D4,Table4[PLAYER NAME],0)) -> 1 | G4: =A4-F4 -> 0 | H4: =G4/F4 -> 0 | I4: =IF(AND(H4 > -1, H4 <= -0.5), "Extremely Overvalued", IF(AND(H4 > -0.5, H4 <= -0.15), "Pretty Overvalued", IF(AND(H4 > -0.15, H4 < 0), "Slightly Overvalued", IF(H4 = 0, "At ADP", IF(AND(H4 > 0, H4 <= 0.15), "Slightly Undervalued", IF(AND(H4 > 0.15, H4 <= 0.5), "Pretty Undervalued", IF(AND(H4 > 0.5, H4 <= 1), "Extremely Undervalued", ""))))))) -> At ADP | J4: =IF(W4=$G$1,"M",IF(AND(U4="Drafted",W4<>$G$1),"Y","")) -> Y | K4: =IF(E4="QB",1,IF(E4="RB",2,IF(E4="WR",3,IF(E4="TE",4,IF(E4="K",5,"Check"))))) -> 2 | L4: =IF(J4="M",COUNTIFS($J$4:J4,"M",$E$4:E4,E4)&" - "&K4,"N/A") -> N/A | M4: =IFERROR(INDEX(PlayerSummaryTable[Rushing Yds],MATCH('Rankings Master'!D4,PlayerSummaryTable[Player],0)),"") -> 1199.5 | N4: =IFERROR(INDEX(PlayerSummaryTable[Receiving Yds],MATCH('Rankings Master'!D4,PlayerSummaryTable[Player],0)),"") -> 449.5 | O4: =IFERROR(INDEX(PlayerSummaryTable[Passing Yds],MATCH('Rankings Master'!D4,PlayerSummaryTable[Player],0)),"") -> N/A | Q4: ="1 - 1" -> 1 - 1 | R4: QB1 | S4: =IFERROR(INDEX($D$4:$D$203,MATCH(Q4,$L$4:$L$203,0)),"") -> Trevor Lawrence | U4: =IF(COUNTIF('Draft Log'!$B$2:$B$301,D4)>0,"DRAFTED","") -> DRAFTED | V4: =IFERROR(INDEX('Draft Log'!$A$2:$A$301,MATCH(D4,'Draft Log'!$B$2:$B$301,0)),"") -> 1 | W4: =IFERROR(INDEX('Draft Log'!$C$2:$C$301,MATCH(D4,'Draft Log'!$B$2:$B$301,0)),"") -> Team Afeef | Z4: {=_xlfn.UNIQUE(_xlfn.SORTBY($W$4:$W$402,$V$4:$V$402,1))} -> Team Afeef | AA4: =COUNTIFS($W$4:$W$402,$Z4,$E$4:$E$402,AA$3) -> 2 | AB4: =COUNTIFS($W$4:$W$402,$Z4,$E$4:$E$402,AB$3) -> 5 | AC4: =COUNTIFS($W$4:$W$402,$Z4,$E$4:$E$402,AC$3) -> 6 | AD4: =COUNTIFS($W$4:$W$402,$Z4,$E$4:$E$402,AD$3) -> 2
A5: 2 | B5: CeeDee | C5: Lamb | D5: =IF($D$1="ESPN",INDEX(Table2[Mapped Name],MATCH('Rankings Master'!$A5,Table2[Overall Rank],0)),IF('Rankings Master'!$D$1="NFL.com",INDEX(Table3[Name Clean],MATCH('Rankings Master'!$A5,Table3[Rank],0)),IF('Rankings Master'!$D$1="Sleeper",INDEX(Sleeper!$B$2:$B$201,MATCH('Rankings Master'!$A5,Sleeper!$A$2:$A$201,0)),"Need platform"))) -> Bijan Robinson | E5: =IF($D$1="ESPN",INDEX(Table2[Position],MATCH('Rankings Master'!$A5,Table2[Overall Rank],0)),IF('Rankings Master'!$D$1="NFL.com",INDEX(Table3[Position],MATCH('Rankings Master'!$A5,Table3[Rank],0)),INDEX(Sleeper!$C$2:$C$201,MATCH('Rankings Master'!A5,Sleeper!$A$2:$A$201,0)))) -> RB | F5: =INDEX(Table4[RK],MATCH('Rankings Master'!D5,Table4[PLAYER NAME],0)) -> 3 | G5: =A5-F5 -> -1 | H5: =G5/F5 -> -0.33333333 | I5: =IF(AND(H5 > -1, H5 <= -0.5), "Extremely Overvalued", IF(AND(H5 > -0.5, H5 <= -0.15), "Pretty Overvalued", IF(AND(H5 > -0.15, H5 < 0), "Slightly Overvalued", IF(H5 = 0, "At ADP", IF(AND(H5 > 0, H5 <= 0.15), "Slightly Undervalued", IF(AND(H5 > 0.15, H5 <= 0.5), "Pretty Undervalued", IF(AND(H5 > 0.5, H5 <= 1), "Extremely Undervalued", ""))))))) -> Pretty Overvalued | J5: =IF(W5=$G$1,"M",IF(AND(U5="Drafted",W5<>$G$1),"Y","")) -> Y | K5: =IF(E5="QB",1,IF(E5="RB",2,IF(E5="WR",3,IF(E5="TE",4,IF(E5="K",5,"Check"))))) -> 2 | L5: =IF(J5="M",COUNTIFS($J$4:J5,"M",$E$4:E5,E5)&" - "&K5,"N/A") -> N/A | M5: =IFERROR(INDEX(PlayerSummaryTable[Rushing Yds],MATCH('Rankings Master'!D5,PlayerSummaryTable[Player],0)),"") -> 1174.5 | N5: =IFERROR(INDEX(PlayerSummaryTable[Receiving Yds],MATCH('Rankings Master'!D5,PlayerSummaryTable[Player],0)),"") -> 574.5 | O5: =IFERROR(INDEX(PlayerSummaryTable[Passing Yds],MATCH('Rankings Master'!D5,PlayerSummaryTable[Player],0)),"") -> N/A | Q5: ="2 - 1" -> 2 - 1 | R5: QB2 | S5: =IFERROR(INDEX($D$4:$D$198,MATCH(Q5,$L$4:$L$198,0)),"") -> Justin Herbert | U5: =IF(COUNTIF('Draft Log'!$B$2:$B$301,D5)>0,"DRAFTED","") -> DRAFTED | V5: =IFERROR(INDEX('Draft Log'!$A$2:$A$301,MATCH(D5,'Draft Log'!$B$2:$B$301,0)),"") -> 2 | W5: =IFERROR(INDEX('Draft Log'!$C$2:$C$301,MATCH(D5,'Draft Log'!$B$2:$B$301,0)),"") -> Benjamins Bandits | Z5: Benjamins Bandits | AA5: =COUNTIFS($W$4:$W$402,$Z5,$E$4:$E$402,AA$3) -> 1 | AB5: =COUNTIFS($W$4:$W$402,$Z5,$E$4:$E$402,AB$3) -> 4 | AC5: =COUNTIFS($W$4:$W$402,$Z5,$E$4:$E$402,AC$3) -> 6 | AD5: =COUNTIFS($W$4:$W$402,$Z5,$E$4:$E$402,AD$3) -> 2
A6: 3 | B6: Tyreek | C6: Hill | D6: =IF($D$1="ESPN",INDEX(Table2[Mapped Name],MATCH('Rankings Master'!$A6,Table2[Overall Rank],0)),IF('Rankings Master'!$D$1="NFL.com",INDEX(Table3[Name Clean],MATCH('Rankings Master'!$A6,Table3[Rank],0)),IF('Rankings Master'!$D$1="Sleeper",INDEX(Sleeper!$B$2:$B$201,MATCH('Rankings Master'!$A6,Sleeper!$A$2:$A$201,0)),"Need platform"))) -> Ja'Marr Chase | E6: =IF($D$1="ESPN",INDEX(Table2[Position],MATCH('Rankings Master'!$A6,Table2[Overall Rank],0)),IF('Rankings Master'!$D$1="NFL.com",INDEX(Table3[Position],MATCH('Rankings Master'!$A6,Table3[Rank],0)),INDEX(Sleeper!$C$2:$C$201,MATCH('Rankings Master'!A6,Sleeper!$A$2:$A$201,0)))) -> WR | F6: =INDEX(Table4[RK],MATCH('Rankings Master'!D6,Table4[PLAYER NAME],0)) -> 2 | G6: =A6-F6 -> 1 | H6: =G6/F6 -> 0.5 | I6: =IF(AND(H6 > -1, H6 <= -0.5), "Extremely Overvalued", IF(AND(H6 > -0.5, H6 <= -0.15), "Pretty Overvalued", IF(AND(H6 > -0.15, H6 < 0), "Slightly Overvalued", IF(H6 = 0, "At ADP", IF(AND(H6 > 0, H6 <= 0.15), "Slightly Undervalued", IF(AND(H6 > 0.15, H6 <= 0.5), "Pretty Undervalued", IF(AND(H6 > 0.5, H6 <= 1), "Extremely Undervalued", ""))))))) -> Pretty Undervalued | J6: =IF(W6=$G$1,"M",IF(AND(U6="Drafted",W6<>$G$1),"Y","")) -> Y | K6: =IF(E6="QB",1,IF(E6="RB",2,IF(E6="WR",3,IF(E6="TE",4,IF(E6="K",5,"Check"))))) -> 3 | L6: =IF(J6="M",COUNTIFS($J$4:J6,"M",$E$4:E6,E6)&" - "&K6,"N/A") -> N/A | M6: =IFERROR(INDEX(PlayerSummaryTable[Rushing Yds],MATCH('Rankings Master'!D6,PlayerSummaryTable[Player],0)),"") -> N/A | N6: =IFERROR(INDEX(PlayerSummaryTable[Receiving Yds],MATCH('Rankings Master'!D6,PlayerSummaryTable[Player],0)),"") -> 1324.5 | O6: =IFERROR(INDEX(PlayerSummaryTable[Passing Yds],MATCH('Rankings Master'!D6,PlayerSummaryTable[Player],0)),"") -> N/A | Q6: ="3 - 1" -> 3 - 1 | R6: QB3 | S6: =IFERROR(INDEX($D$4:$D$198,MATCH(Q6,$L$4:$L$198,0)),"") | U6: =IF(COUNTIF('Draft Log'!$B$2:$B$301,D6)>0,"DRAFTED","") -> DRAFTED | V6: =IFERROR(INDEX('Draft Log'!$A$2:$A$301,MATCH(D6,'Draft Log'!$B$2:$B$301,0)),"") -> 3 | W6: =IFERROR(INDEX('Draft Log'!$C$2:$C$301,MATCH(D6,'Draft Log'!$B$2:$B$301,0)),"") -> dontsaynosayYA | Z6: dontsaynosayYA | AA6: =COUNTIFS($W$4:$W$402,$Z6,$E$4:$E$402,AA$3) -> 2 | AB6: =COUNTIFS($W$4:$W$402,$Z6,$E$4:$E$402,AB$3) -> 4 | AC6: =COUNTIFS($W$4:$W$402,$Z6,$E$4:$E$402,AC$3) -> 5 | AD6: =COUNTIFS($W$4:$W$402,$Z6,$E$4:$E$402,AD$3) -> 3
A7: 4 | B7: Ja'Marr | C7: Chase | D7: =IF($D$1="ESPN",INDEX(Table2[Mapped Name],MATCH('Rankings Master'!$A7,Table2[Overall Rank],0)),IF('Rankings Master'!$D$1="NFL.com",INDEX(Table3[Name Clean],MATCH('Rankings Master'!$A7,Table3[Rank],0)),IF('Rankings Master'!$D$1="Sleeper",INDEX(Sleeper!$B$2:$B$201,MATCH('Rankings Master'!$A7,Sleeper!$A$2:$A$201,0)),"Need platform"))) -> Puka Nacua | E7: =IF($D$1="ESPN",INDEX(Table2[Position],MATCH('Rankings Master'!$A7,Table2[Overall Rank],0)),IF('Rankings Master'!$D$1="NFL.com",INDEX(Table3[Position],MATCH('Rankings Master'!$A7,Table3[Rank],0)),INDEX(Sleeper!$C$2:$C$201,MATCH('Rankings Master'!A7,Sleeper!$A$2:$A$201,0)))) -> WR | F7: =INDEX(Table4[RK],MATCH('Rankings Master'!D7,Table4[PLAYER NAME],0)) -> 4 | G7: =A7-F7 -> 0 | H7: =G7/F7 -> 0 | I7: =IF(AND(H7 > -1, H7 <= -0.5), "Extremely Overvalued", IF(AND(H7 > -0.5, H7 <= -0.15), "Pretty Overvalued", IF(AND(H7 > -0.15, H7 < 0), "Slightly Overvalued", IF(H7 = 0, "At ADP", IF(AND(H7 > 0, H7 <= 0.15), "Slightly Undervalued", IF(AND(H7 > 0.15, H7 <= 0.5), "Pretty Undervalued", IF(AND(H7 > 0.5, H7 <= 1), "Extremely Undervalued", ""))))))) -> At ADP | J7: =IF(W7=$G$1,"M",IF(AND(U7="Drafted",W7<>$G$1),"Y","")) -> Y | K7: =IF(E7="QB",1,IF(E7="RB",2,IF(E7="WR",3,IF(E7="TE",4,IF(E7="K",5,"Check"))))) -> 3 | L7: =IF(J7="M",COUNTIFS($J$4:J7,"M",$E$4:E7,E7)&" - "&K7,"N/A") -> N/A | M7: =IFERROR(INDEX(PlayerSummaryTable[Rushing Yds],MATCH('Rankings Master'!D7,PlayerSummaryTable[Player],0)),"") -> N/A | N7: =IFERROR(INDEX(PlayerSummaryTable[Receiving Yds],MATCH('Rankings Master'!D7,PlayerSummaryTable[Player],0)),"") -> 1324.5 | O7: =IFERROR(INDEX(PlayerSummaryTable[Passing Yds],MATCH('Rankings Master'!D7,PlayerSummaryTable[Player],0)),"") -> N/A | Q7: ="1 - 2" -> 1 - 2 | R7: RB1 | S7: =IFERROR(INDEX($D$4:$D$198,MATCH(Q7,$L$4:$L$198,0)),"") -> James Cook III | U7: =IF(COUNTIF('Draft Log'!$B$2:$B$301,D7)>0,"DRAFTED","") -> DRAFTED | V7: =IFERROR(INDEX('Draft Log'!$A$2:$A$301,MATCH(D7,'Draft Log'!$B$2:$B$301,0)),"") -> 4 | W7: =IFERROR(INDEX('Draft Log'!$C$2:$C$301,MATCH(D7,'Draft Log'!$B$2:$B$301,0)),"") -> Cut to the Chase | Z7: Cut to the Chase | AA7: =COUNTIFS($W$4:$W$402,$Z7,$E$4:$E$402,AA$3) -> 1 | AB7: =COUNTIFS($W$4:$W$402,$Z7,$E$4:$E$402,AB$3) -> 5 | AC7: =COUNTIFS($W$4:$W$402,$Z7,$E$4:$E$402,AC$3) -> 7 | AD7: =COUNTIFS($W$4:$W$402,$Z7,$E$4:$E$402,AD$3) -> 2
A8: 5 | B8: Amon-Ra | C8: St. Brown | D8: =IF($D$1="ESPN",INDEX(Table2[Mapped Name],MATCH('Rankings Master'!$A8,Table2[Overall Rank],0)),IF('Rankings Master'!$D$1="NFL.com",INDEX(Table3[Name Clean],MATCH('Rankings Master'!$A8,Table3[Rank],0)),IF('Rankings Master'!$D$1="Sleeper",INDEX(Sleeper!$B$2:$B$201,MATCH('Rankings Master'!$A8,Sleeper!$A$2:$A$201,0)),"Need platform"))) -> Jaxon Smith-Njigba | E8: =IF($D$1="ESPN",INDEX(Table2[Position],MATCH('Rankings Master'!$A8,Table2[Overall Rank],0)),IF('Rankings Master'!$D$1="NFL.com",INDEX(Table3[Position],MATCH('Rankings Master'!$A8,Table3[Rank],0)),INDEX(Sleeper!$C$2:$C$201,MATCH('Rankings Master'!A8,Sleeper!$A$2:$A$201,0)))) -> WR | F8: =INDEX(Table4[RK],MATCH('Rankings Master'!D8,Table4[PLAYER NAME],0)) -> 5 | G8: =A8-F8 -> 0 | H8: =G8/F8 -> 0 | I8: =IF(AND(H8 > -1, H8 <= -0.5), "Extremely Overvalued", IF(AND(H8 > -0.5, H8 <= -0.15), "Pretty Overvalued", IF(AND(H8 > -0.15, H8 < 0), "Slightly Overvalued", IF(H8 = 0, "At ADP", IF(AND(H8 > 0, H8 <= 0.15), "Slightly Undervalued", IF(AND(H8 > 0.15, H8 <= 0.5), "Pretty Undervalued", IF(AND(H8 > 0.5, H8 <= 1), "Extremely Undervalued", ""))))))) -> At ADP | J8: =IF(W8=$G$1,"M",IF(AND(U8="Drafted",W8<>$G$1),"Y","")) -> Y | K8: =IF(E8="QB",1,IF(E8="RB",2,IF(E8="WR",3,IF(E8="TE",4,IF(E8="K",5,"Check"))))) -> 3 | L8: =IF(J8="M",COUNTIFS($J$4:J8,"M",$E$4:E8,E8)&" - "&K8,"N/A") -> N/A | M8: =IFERROR(INDEX(PlayerSummaryTable[Rushing Yds],MATCH('Rankings Master'!D8,PlayerSummaryTable[Player],0)),"") -> N/A | N8: =IFERROR(INDEX(PlayerSummaryTable[Receiving Yds],MATCH('Rankings Master'!D8,PlayerSummaryTable[Player],0)),"") -> 1324.5 | O8: =IFERROR(INDEX(PlayerSummaryTable[Passing Yds],MATCH('Rankings Master'!D8,PlayerSummaryTable[Player],0)),"") -> N/A | Q8: ="2 - 2" -> 2 - 2 | R8: RB2 | S8: =IFERROR(INDEX($D$4:$D$198,MATCH(Q8,$L$4:$L$198,0)),"") -> Omarion Hampton | U8: =IF(COUNTIF('Draft Log'!$B$2:$B$301,D8)>0,"DRAFTED","") -> DRAFTED | V8: =IFERROR(INDEX('Draft Log'!$A$2:$A$301,MATCH(D8,'Draft Log'!$B$2:$B$301,0)),"") -> 5 | W8: =IFERROR(INDEX('Draft Log'!$C$2:$C$301,MATCH(D8,'Draft Log'!$B$2:$B$301,0)),"") -> JJetts Skatt Hurts | Z8: JJetts Skatt Hurts | AA8: =COUNTIFS($W$4:$W$402,$Z8,$E$4:$E$402,AA$3) -> 1 | AB8: =COUNTIFS($W$4:$W$402,$Z8,$E$4:$E$402,AB$3) -> 7 | AC8: =COUNTIFS($W$4:$W$402,$Z8,$E$4:$E$402,AC$3) -> 6 | AD8: =COUNTIFS($W$4:$W$402,$Z8,$E$4:$E$402,AD$3) -> 1
A9: 6 | B9: Justin | C9: Jefferson | D9: =IF($D$1="ESPN",INDEX(Table2[Mapped Name],MATCH('Rankings Master'!$A9,Table2[Overall Rank],0)),IF('Rankings Master'!$D$1="NFL.com",INDEX(Table3[Name Clean],MATCH('Rankings Master'!$A9,Table3[Rank],0)),IF('Rankings Master'!$D$1="Sleeper",INDEX(Sleeper!$B$2:$B$201,MATCH('Rankings Master'!$A9,Sleeper!$A$2:$A$201,0)),"Need platform"))) -> Christian McCaffrey | E9: =IF($D$1="ESPN",INDEX(Table2[Position],MATCH('Rankings Master'!$A9,Table2[Overall Rank],0)),IF('Rankings Master'!$D$1="NFL.com",INDEX(Table3[Position],MATCH('Rankings Master'!$A9,Table3[Rank],0)),INDEX(Sleeper!$C$2:$C$201,MATCH('Rankings Master'!A9,Sleeper!$A$2:$A$201,0)))) -> RB | F9: =INDEX(Table4[RK],MATCH('Rankings Master'!D9,Table4[PLAYER NAME],0)) -> 9 | G9: =A9-F9 -> -3 | H9: =G9/F9 -> -0.33333333 | I9: =IF(AND(H9 > -1, H9 <= -0.5), "Extremely Overvalued", IF(AND(H9 > -0.5, H9 <= -0.15), "Pretty Overvalued", IF(AND(H9 > -0.15, H9 < 0), "Slightly Overvalued", IF(H9 = 0, "At ADP", IF(AND(H9 > 0, H9 <= 0.15), "Slightly Undervalued", IF(AND(H9 > 0.15, H9 <= 0.5), "Pretty Undervalued", IF(AND(H9 > 0.5, H9 <= 1), "Extremely Undervalued", ""))))))) -> Pretty Overvalued | J9: =IF(W9=$G$1,"M",IF(AND(U9="Drafted",W9<>$G$1),"Y","")) -> Y | K9: =IF(E9="QB",1,IF(E9="RB",2,IF(E9="WR",3,IF(E9="TE",4,IF(E9="K",5,"Check"))))) -> 2 | L9: =IF(J9="M",COUNTIFS($J$4:J9,"M",$E$4:E9,E9)&" - "&K9,"N/A") -> N/A | M9: =IFERROR(INDEX(PlayerSummaryTable[Rushing Yds],MATCH('Rankings Master'!D9,PlayerSummaryTable[Player],0)),"") -> 949.5 | N9: =IFERROR(INDEX(PlayerSummaryTable[Receiving Yds],MATCH('Rankings Master'!D9,PlayerSummaryTable[Player],0)),"") -> 574.5 | O9: =IFERROR(INDEX(PlayerSummaryTable[Passing Yds],MATCH('Rankings Master'!D9,PlayerSummaryTable[Player],0)),"") -> N/A | Q9: ="3 - 2" -> 3 - 2 | R9: RB3 | S9: =IFERROR(INDEX($D$4:$D$198,MATCH(Q9,$L$4:$L$198,0)),"") -> Kenny Gainwell | U9: =IF(COUNTIF('Draft Log'!$B$2:$B$301,D9)>0,"DRAFTED","") -> DRAFTED | V9: =IFERROR(INDEX('Draft Log'!$A$2:$A$301,MATCH(D9,'Draft Log'!$B$2:$B$301,0)),"") -> 10 | W9: =IFERROR(INDEX('Draft Log'!$C$2:$C$301,MATCH(D9,'Draft Log'!$B$2:$B$301,0)),"") -> Double Chubb Chocolate Cookie | Z9: BEST COUNTRY IN THE WORLD | AA9: =COUNTIFS($W$4:$W$402,$Z9,$E$4:$E$402,AA$3) -> 2 | AB9: =COUNTIFS($W$4:$W$402,$Z9,$E$4:$E$402,AB$3) -> 5 | AC9: =COUNTIFS($W$4:$W$402,$Z9,$E$4:$E$402,AC$3) -> 6 | AD9: =COUNTIFS($W$4:$W$402,$Z9,$E$4:$E$402,AD$3) -> 2
A10: 7 | B10: Breece | C10: Hall | D10: =IF($D$1="ESPN",INDEX(Table2[Mapped Name],MATCH('Rankings Master'!$A10,Table2[Overall Rank],0)),IF('Rankings Master'!$D$1="NFL.com",INDEX(Table3[Name Clean],MATCH('Rankings Master'!$A10,Table3[Rank],0)),IF('Rankings Master'!$D$1="Sleeper",INDEX(Sleeper!$B$2:$B$201,MATCH('Rankings Master'!$A10,Sleeper!$A$2:$A$201,0)),"Need platform"))) -> Jonathan Taylor | E10: =IF($D$1="ESPN",INDEX(Table2[Position],MATCH('Rankings Master'!$A10,Table2[Overall Rank],0)),IF('Rankings Master'!$D$1="NFL.com",INDEX(Table3[Position],MATCH('Rankings Master'!$A10,Table3[Rank],0)),INDEX(Sleeper!$C$2:$C$201,MATCH('Rankings Master'!A10,Sleeper!$A$2:$A$201,0)))) -> RB | F10: =INDEX(Table4[RK],MATCH('Rankings Master'!D10,Table4[PLAYER NAME],0)) -> 7 | G10: =A10-F10 -> 0 | H10: =G10/F10 -> 0 | I10: =IF(AND(H10 > -1, H10 <= -0.5), "Extremely Overvalued", IF(AND(H10 > -0.5, H10 <= -0.15), "Pretty Overvalued", IF(AND(H10 > -0.15, H10 < 0), "Slightly Overvalued", IF(H10 = 0, "At ADP", IF(AND(H10 > 0, H10 <= 0.15), "Slightly Undervalued", IF(AND(H10 > 0.15, H10 <= 0.5), "Pretty Undervalued", IF(AND(H10 > 0.5, H10 <= 1), "Extremely Undervalued", ""))))))) -> At ADP | J10: =IF(W10=$G$1,"M",IF(AND(U10="Drafted",W10<>$G$1),"Y","")) -> Y | K10: =IF(E10="QB",1,IF(E10="RB",2,IF(E10="WR",3,IF(E10="TE",4,IF(E10="K",5,"Check"))))) -> 2 | L10: =IF(J10="M",COUNTIFS($J$4:J10,"M",$E$4:E10,E10)&" - "&K10,"N/A") -> N/A | M10: =IFERROR(INDEX(PlayerSummaryTable[Rushing Yds],MATCH('Rankings Master'!D10,PlayerSummaryTable[Player],0)),"") -> 1224.5 | N10: =IFERROR(INDEX(PlayerSummaryTable[Receiving Yds],MATCH('Rankings Master'!D10,PlayerSummaryTable[Player],0)),"") -> N/A | O10: =IFERROR(INDEX(PlayerSummaryTable[Passing Yds],MATCH('Rankings Master'!D10,PlayerSummaryTable[Player],0)),"") -> N/A | Q10: ="4 - 2" -> 4 - 2 | R10: RB4 | S10: =IFERROR(INDEX($D$4:$D$198,MATCH(Q10,$L$4:$L$198,0)),"") -> Blake Corum | U10: =IF(COUNTIF('Draft Log'!$B$2:$B$301,D10)>0,"DRAFTED","") -> DRAFTED | V10: =IFERROR(INDEX('Draft Log'!$A$2:$A$301,MATCH(D10,'Draft Log'!$B$2:$B$301,0)),"") -> 7 | W10: =IFERROR(INDEX('Draft Log'!$C$2:$C$301,MATCH(D10,'Draft Log'!$B$2:$B$301,0)),"") -> Eight Bell Tolls | Z10: Eight Bell Tolls | AA10: =COUNTIFS($W$4:$W$402,$Z10,$E$4:$E$402,AA$3) -> 2 | AB10: =COUNTIFS($W$4:$W$402,$Z10,$E$4:$E$402,AB$3) -> 6 | AC10: =COUNTIFS($W$4:$W$402,$Z10,$E$4:$E$402,AC$3) -> 5 | AD10: =COUNTIFS($W$4:$W$402,$Z10,$E$4:$E$402,AD$3) -> 1
A11: 8 | B11: Bijan | C11: Robinson | D11: =IF($D$1="ESPN",INDEX(Table2[Mapped Name],MATCH('Rankings Master'!$A11,Table2[Overall Rank],0)),IF('Rankings Master'!$D$1="NFL.com",INDEX(Table3[Name Clean],MATCH('Rankings Master'!$A11,Table3[Rank],0)),IF('Rankings Master'!$D$1="Sleeper",INDEX(Sleeper!$B$2:$B$201,MATCH('Rankings Master'!$A11,Sleeper!$A$2:$A$201,0)),"Need platform"))) -> Amon-Ra St. Brown | E11: =IF($D$1="ESPN",INDEX(Table2[Position],MATCH('Rankings Master'!$A11,Table2[Overall Rank],0)),IF('Rankings Master'!$D$1="NFL.com",INDEX(Table3[Position],MATCH('Rankings Master'!$A11,Table3[Rank],0)),INDEX(Sleeper!$C$2:$C$201,MATCH('Rankings Master'!A11,Sleeper!$A$2:$A$201,0)))) -> WR | F11: =INDEX(Table4[RK],MATCH('Rankings Master'!D11,Table4[PLAYER NAME],0)) -> 6 | G11: =A11-F11 -> 2 | H11: =G11/F11 -> 0.33333333 | I11: =IF(AND(H11 > -1, H11 <= -0.5), "Extremely Overvalued", IF(AND(H11 > -0.5, H11 <= -0.15), "Pretty Overvalued", IF(AND(H11 > -0.15, H11 < 0), "Slightly Overvalued", IF(H11 = 0, "At ADP", IF(AND(H11 > 0, H11 <= 0.15), "Slightly Undervalued", IF(AND(H11 > 0.15, H11 <= 0.5), "Pretty Undervalued", IF(AND(H11 > 0.5, H11 <= 1), "Extremely Undervalued", ""))))))) -> Pretty Undervalued | J11: =IF(W11=$G$1,"M",IF(AND(U11="Drafted",W11<>$G$1),"Y","")) -> Y | K11: =IF(E11="QB",1,IF(E11="RB",2,IF(E11="WR",3,IF(E11="TE",4,IF(E11="K",5,"Check"))))) -> 3 | L11: =IF(J11="M",COUNTIFS($J$4:J11,"M",$E$4:E11,E11)&" - "&K11,"N/A") -> N/A | M11: =IFERROR(INDEX(PlayerSummaryTable[Rushing Yds],MATCH('Rankings Master'!D11,PlayerSummaryTable[Player],0)),"") | N11: =IFERROR(INDEX(PlayerSummaryTable[Receiving Yds],MATCH('Rankings Master'!D11,PlayerSummaryTable[Player],0)),"") | O11: =IFERROR(INDEX(PlayerSummaryTable[Passing Yds],MATCH('Rankings Master'!D11,PlayerSummaryTable[Player],0)),"") | Q11: ="5 - 2" -> 5 - 2 | R11: RB5 | S11: =IFERROR(INDEX($D$4:$D$198,MATCH(Q11,$L$4:$L$198,0)),"") -> Chris Rodriguez Jr. | U11: =IF(COUNTIF('Draft Log'!$B$2:$B$301,D11)>0,"DRAFTED","") -> DRAFTED | V11: =IFERROR(INDEX('Draft Log'!$A$2:$A$301,MATCH(D11,'Draft Log'!$B$2:$B$301,0)),"") -> 6 | W11: =IFERROR(INDEX('Draft Log'!$C$2:$C$301,MATCH(D11,'Draft Log'!$B$2:$B$301,0)),"") -> BEST COUNTRY IN THE WORLD | Z11: Mustafa is Not Like Us | AA11: =COUNTIFS($W$4:$W$402,$Z11,$E$4:$E$402,AA$3) -> 2 | AB11: =COUNTIFS($W$4:$W$402,$Z11,$E$4:$E$402,AB$3) -> 7 | AC11: =COUNTIFS($W$4:$W$402,$Z11,$E$4:$E$402,AC$3) -> 5 | AD11: =COUNTIFS($W$4:$W$402,$Z11,$E$4:$E$402,AD$3) -> 1
A12: 9 | B12: A.J. | C12: Brown | D12: =IF($D$1="ESPN",INDEX(Table2[Mapped Name],MATCH('Rankings Master'!$A12,Table2[Overall Rank],0)),IF('Rankings Master'!$D$1="NFL.com",INDEX(Table3[Name Clean],MATCH('Rankings Master'!$A12,Table3[Rank],0)),IF('Rankings Master'!$D$1="Sleeper",INDEX(Sleeper!$B$2:$B$201,MATCH('Rankings Master'!$A12,Sleeper!$A$2:$A$201,0)),"Need platform"))) -> CeeDee Lamb | E12: =IF($D$1="ESPN",INDEX(Table2[Position],MATCH('Rankings Master'!$A12,Table2[Overall Rank],0)),IF('Rankings Master'!$D$1="NFL.com",INDEX(Table3[Position],MATCH('Rankings Master'!$A12,Table3[Rank],0)),INDEX(Sleeper!$C$2:$C$201,MATCH('Rankings Master'!A12,Sleeper!$A$2:$A$201,0)))) -> WR | F12: =INDEX(Table4[RK],MATCH('Rankings Master'!D12,Table4[PLAYER NAME],0)) -> 10 | G12: =A12-F12 -> -1 | H12: =G12/F12 -> -0.1 | I12: =IF(AND(H12 > -1, H12 <= -0.5), "Extremely Overvalued", IF(AND(H12 > -0.5, H12 <= -0.15), "Pretty Overvalued", IF(AND(H12 > -0.15, H12 < 0), "Slightly Overvalued", IF(H12 = 0, "At ADP", IF(AND(H12 > 0, H12 <= 0.15), "Slightly Undervalued", IF(AND(H12 > 0.15, H12 <= 0.5), "Pretty Undervalued", IF(AND(H12 > 0.5, H12 <= 1), "Extremely Undervalued", ""))))))) -> Slightly Overvalued | J12: =IF(W12=$G$1,"M",IF(AND(U12="Drafted",W12<>$G$1),"Y","")) -> Y | K12: =IF(E12="QB",1,IF(E12="RB",2,IF(E12="WR",3,IF(E12="TE",4,IF(E12="K",5,"Check"))))) -> 3 | L12: =IF(J12="M",COUNTIFS($J$4:J12,"M",$E$4:E12,E12)&" - "&K12,"N/A") -> N/A | M12: =IFERROR(INDEX(PlayerSummaryTable[Rushing Yds],MATCH('Rankings Master'!D12,PlayerSummaryTable[Player],0)),"") -> N/A | N12: =IFERROR(INDEX(PlayerSummaryTable[Receiving Yds],MATCH('Rankings Master'!D12,PlayerSummaryTable[Player],0)),"") -> 1199.5 | O12: =IFERROR(INDEX(PlayerSummaryTable[Passing Yds],MATCH('Rankings Master'!D12,PlayerSummaryTable[Player],0)),"") -> N/A | Q12: ="6 - 2" -> 6 - 2 | R12: RB6 | S12: =IFERROR(INDEX($D$4:$D$198,MATCH(Q12,$L$4:$L$198,0)),"") -> Tyler Allgeier | U12: =IF(COUNTIF('Draft Log'!$B$2:$B$301,D12)>0,"DRAFTED","") -> DRAFTED | V12: =IFERROR(INDEX('Draft Log'!$A$2:$A$301,MATCH(D12,'Draft Log'!$B$2:$B$301,0)),"") -> 9 | W12: =IFERROR(INDEX('Draft Log'!$C$2:$C$301,MATCH(D12,'Draft Log'!$B$2:$B$301,0)),"") -> The Good, Bad and Ugly | Z12: The Good, Bad and Ugly | AA12: =COUNTIFS($W$4:$W$402,$Z12,$E$4:$E$402,AA$3) -> 2 | AB12: =COUNTIFS($W$4:$W$402,$Z12,$E$4:$E$402,AB$3) -> 4 | AC12: =COUNTIFS($W$4:$W$402,$Z12,$E$4:$E$402,AC$3) -> 7 | AD12: =COUNTIFS($W$4:$W$402,$Z12,$E$4:$E$402,AD$3) -> 2
A13: 10 | B13: Puka | C13: Nacua | D13: =IF($D$1="ESPN",INDEX(Table2[Mapped Name],MATCH('Rankings Master'!$A13,Table2[Overall Rank],0)),IF('Rankings Master'!$D$1="NFL.com",INDEX(Table3[Name Clean],MATCH('Rankings Master'!$A13,Table3[Rank],0)),IF('Rankings Master'!$D$1="Sleeper",INDEX(Sleeper!$B$2:$B$201,MATCH('Rankings Master'!$A13,Sleeper!$A$2:$A$201,0)),"Need platform"))) -> Justin Jefferson | E13: =IF($D$1="ESPN",INDEX(Table2[Position],MATCH('Rankings Master'!$A13,Table2[Overall Rank],0)),IF('Rankings Master'!$D$1="NFL.com",INDEX(Table3[Position],MATCH('Rankings Master'!$A13,Table3[Rank],0)),INDEX(Sleeper!$C$2:$C$201,MATCH('Rankings Master'!A13,Sleeper!$A$2:$A$201,0)))) -> WR | F13: =INDEX(Table4[RK],MATCH('Rankings Master'!D13,Table4[PLAYER NAME],0)) -> 11 | G13: =A13-F13 -> -1 | H13: =G13/F13 -> -0.090909091 | I13: =IF(AND(H13 > -1, H13 <= -0.5), "Extremely Overvalued", IF(AND(H13 > -0.5, H13 <= -0.15), "Pretty Overvalued", IF(AND(H13 > -0.15, H13 < 0), "Slightly Overvalued", IF(H13 = 0, "At ADP", IF(AND(H13 > 0, H13 <= 0.15), "Slightly Undervalued", IF(AND(H13 > 0.15, H13 <= 0.5), "Pretty Undervalued", IF(AND(H13 > 0.5, H13 <= 1), "Extremely Undervalued", ""))))))) -> Slightly Overvalued | J13: =IF(W13=$G$1,"M",IF(AND(U13="Drafted",W13<>$G$1),"Y","")) -> Y | K13: =IF(E13="QB",1,IF(E13="RB",2,IF(E13="WR",3,IF(E13="TE",4,IF(E13="K",5,"Check"))))) -> 3 | L13: =IF(J13="M",COUNTIFS($J$4:J13,"M",$E$4:E13,E13)&" - "&K13,"N/A") -> N/A | M13: =IFERROR(INDEX(PlayerSummaryTable[Rushing Yds],MATCH('Rankings Master'!D13,PlayerSummaryTable[Player],0)),"") -> N/A | N13: =IFERROR(INDEX(PlayerSummaryTable[Receiving Yds],MATCH('Rankings Master'!D13,PlayerSummaryTable[Player],0)),"") -> 1174.5 | O13: =IFERROR(INDEX(PlayerSummaryTable[Passing Yds],MATCH('Rankings Master'!D13,PlayerSummaryTable[Player],0)),"") -> N/A | Q13: ="1 - 3" -> 1 - 3 | R13: WR1 | S13: =IFERROR(INDEX($D$4:$D$198,MATCH(Q13,$L$4:$L$198,0)),"") -> DeVonta Smith | U13: =IF(COUNTIF('Draft Log'!$B$2:$B$301,D13)>0,"DRAFTED","") -> DRAFTED | V13: =IFERROR(INDEX('Draft Log'!$A$2:$A$301,MATCH(D13,'Draft Log'!$B$2:$B$301,0)),"") -> 11 | W13: =IFERROR(INDEX('Draft Log'!$C$2:$C$301,MATCH(D13,'Draft Log'!$B$2:$B$301,0)),"") -> Double Chubb Chocolate Cookie | Z13: Double Chubb Chocolate Cookie | AA13: =COUNTIFS($W$4:$W$402,$Z13,$E$4:$E$402,AA$3) -> 1 | AB13: =COUNTIFS($W$4:$W$402,$Z13,$E$4:$E$402,AB$3) -> 7 | AC13: =COUNTIFS($W$4:$W$402,$Z13,$E$4:$E$402,AC$3) -> 6 | AD13: =COUNTIFS($W$4:$W$402,$Z13,$E$4:$E$402,AD$3) -> 1
A14: 11 | B14: Garrett | C14: Wilson | D14: =IF($D$1="ESPN",INDEX(Table2[Mapped Name],MATCH('Rankings Master'!$A14,Table2[Overall Rank],0)),IF('Rankings Master'!$D$1="NFL.com",INDEX(Table3[Name Clean],MATCH('Rankings Master'!$A14,Table3[Rank],0)),IF('Rankings Master'!$D$1="Sleeper",INDEX(Sleeper!$B$2:$B$201,MATCH('Rankings Master'!$A14,Sleeper!$A$2:$A$201,0)),"Need platform"))) -> Derrick Henry | E14: =IF($D$1="ESPN",INDEX(Table2[Position],MATCH('Rankings Master'!$A14,Table2[Overall Rank],0)),IF('Rankings Master'!$D$1="NFL.com",INDEX(Table3[Position],MATCH('Rankings Master'!$A14,Table3[Rank],0)),INDEX(Sleeper!$C$2:$C$201,MATCH('Rankings Master'!A14,Sleeper!$A$2:$A$201,0)))) -> RB | F14: =INDEX(Table4[RK],MATCH('Rankings Master'!D14,Table4[PLAYER NAME],0)) -> 14 | G14: =A14-F14 -> -3 | H14: =G14/F14 -> -0.21428571 | I14: =IF(AND(H14 > -1, H14 <= -0.5), "Extremely Overvalued", IF(AND(H14 > -0.5, H14 <= -0.15), "Pretty Overvalued", IF(AND(H14 > -0.15, H14 < 0), "Slightly Overvalued", IF(H14 = 0, "At ADP", IF(AND(H14 > 0, H14 <= 0.15), "Slightly Undervalued", IF(AND(H14 > 0.15, H14 <= 0.5), "Pretty Undervalued", IF(AND(H14 > 0.5, H14 <= 1), "Extremely Undervalued", ""))))))) -> Pretty Overvalued | J14: =IF(W14=$G$1,"M",IF(AND(U14="Drafted",W14<>$G$1),"Y","")) -> Y | K14: =IF(E14="QB",1,IF(E14="RB",2,IF(E14="WR",3,IF(E14="TE",4,IF(E14="K",5,"Check"))))) -> 2 | L14: =IF(J14="M",COUNTIFS($J$4:J14,"M",$E$4:E14,E14)&" - "&K14,"N/A") -> N/A | M14: =IFERROR(INDEX(PlayerSummaryTable[Rushing Yds],MATCH('Rankings Master'!D14,PlayerSummaryTable[Player],0)),"") -> 1249.5 | N14: =IFERROR(INDEX(PlayerSummaryTable[Receiving Yds],MATCH('Rankings Master'!D14,PlayerSummaryTable[Player],0)),"") -> N/A | O14: =IFERROR(INDEX(PlayerSummaryTable[Passing Yds],MATCH('Rankings Master'!D14,PlayerSummaryTable[Player],0)),"") -> N/A | Q14: ="2 - 3" -> 2 - 3 | R14: WR2 | S14: =IFERROR(INDEX($D$4:$D$198,MATCH(Q14,$L$4:$L$198,0)),"") -> Jameson Williams | U14: =IF(COUNTIF('Draft Log'!$B$2:$B$301,D14)>0,"DRAFTED","") -> DRAFTED | V14: =IFERROR(INDEX('Draft Log'!$A$2:$A$301,MATCH(D14,'Draft Log'!$B$2:$B$301,0)),"") -> 12 | W14: =IFERROR(INDEX('Draft Log'!$C$2:$C$301,MATCH(D14,'Draft Log'!$B$2:$B$301,0)),"") -> The Good, Bad and Ugly
A15: 12 | B15: Saquon | C15: Barkley | D15: =IF($D$1="ESPN",INDEX(Table2[Mapped Name],MATCH('Rankings Master'!$A15,Table2[Overall Rank],0)),IF('Rankings Master'!$D$1="NFL.com",INDEX(Table3[Name Clean],MATCH('Rankings Master'!$A15,Table3[Rank],0)),IF('Rankings Master'!$D$1="Sleeper",INDEX(Sleeper!$B$2:$B$201,MATCH('Rankings Master'!$A15,Sleeper!$A$2:$A$201,0)),"Need platform"))) -> James Cook III | E15: =IF($D$1="ESPN",INDEX(Table2[Position],MATCH('Rankings Master'!$A15,Table2[Overall Rank],0)),IF('Rankings Master'!$D$1="NFL.com",INDEX(Table3[Position],MATCH('Rankings Master'!$A15,Table3[Rank],0)),INDEX(Sleeper!$C$2:$C$201,MATCH('Rankings Master'!A15,Sleeper!$A$2:$A$201,0)))) -> RB | F15: =INDEX(Table4[RK],MATCH('Rankings Master'!D15,Table4[PLAYER NAME],0)) -> 8 | G15: =A15-F15 -> 4 | H15: =G15/F15 -> 0.5 | I15: =IF(AND(H15 > -1, H15 <= -0.5), "Extremely Overvalued", IF(AND(H15 > -0.5, H15 <= -0.15), "Pretty Overvalued", IF(AND(H15 > -0.15, H15 < 0), "Slightly Overvalued", IF(H15 = 0, "At ADP", IF(AND(H15 > 0, H15 <= 0.15), "Slightly Undervalued", IF(AND(H15 > 0.15, H15 <= 0.5), "Pretty Undervalued", IF(AND(H15 > 0.5, H15 <= 1), "Extremely Undervalued", ""))))))) -> Pretty Undervalued | J15: =IF(W15=$G$1,"M",IF(AND(U15="Drafted",W15<>$G$1),"Y","")) -> M | K15: =IF(E15="QB",1,IF(E15="RB",2,IF(E15="WR",3,IF(E15="TE",4,IF(E15="K",5,"Check"))))) -> 2 | L15: =IF(J15="M",COUNTIFS($J$4:J15,"M",$E$4:E15,E15)&" - "&K15,"N/A") -> 1 - 2 | M15: =IFERROR(INDEX(PlayerSummaryTable[Rushing Yds],MATCH('Rankings Master'!D15,PlayerSummaryTable[Player],0)),"") | N15: =IFERROR(INDEX(PlayerSummaryTable[Receiving Yds],MATCH('Rankings Master'!D15,PlayerSummaryTable[Player],0)),"") | O15: =IFERROR(INDEX(PlayerSummaryTable[Passing Yds],MATCH('Rankings Master'!D15,PlayerSummaryTable[Player],0)),"") | Q15: ="3 - 3" -> 3 - 3 | R15: WR3 | S15: =IFERROR(INDEX($D$4:$D$198,MATCH(Q15,$L$4:$L$198,0)),"") -> Luther Burden III | U15: =IF(COUNTIF('Draft Log'!$B$2:$B$301,D15)>0,"DRAFTED","") -> DRAFTED | V15: =IFERROR(INDEX('Draft Log'!$A$2:$A$301,MATCH(D15,'Draft Log'!$B$2:$B$301,0)),"") -> 8 | W15: =IFERROR(INDEX('Draft Log'!$C$2:$C$301,MATCH(D15,'Draft Log'!$B$2:$B$301,0)),"") -> Mustafa is Not Like Us
A16: 13 | B16: Jonathan | C16: Taylor | D16: =IF($D$1="ESPN",INDEX(Table2[Mapped Name],MATCH('Rankings Master'!$A16,Table2[Overall Rank],0)),IF('Rankings Master'!$D$1="NFL.com",INDEX(Table3[Name Clean],MATCH('Rankings Master'!$A16,Table3[Rank],0)),IF('Rankings Master'!$D$1="Sleeper",INDEX(Sleeper!$B$2:$B$201,MATCH('Rankings Master'!$A16,Sleeper!$A$2:$A$201,0)),"Need platform"))) -> De'Von Achane | E16: =IF($D$1="ESPN",INDEX(Table2[Position],MATCH('Rankings Master'!$A16,Table2[Overall Rank],0)),IF('Rankings Master'!$D$1="NFL.com",INDEX(Table3[Position],MATCH('Rankings Master'!$A16,Table3[Rank],0)),INDEX(Sleeper!$C$2:$C$201,MATCH('Rankings Master'!A16,Sleeper!$A$2:$A$201,0)))) -> RB | F16: =INDEX(Table4[RK],MATCH('Rankings Master'!D16,Table4[PLAYER NAME],0)) -> 23 | G16: =A16-F16 -> -10 | H16: =G16/F16 -> -0.43478261 | I16: =IF(AND(H16 > -1, H16 <= -0.5), "Extremely Overvalued", IF(AND(H16 > -0.5, H16 <= -0.15), "Pretty Overvalued", IF(AND(H16 > -0.15, H16 < 0), "Slightly Overvalued", IF(H16 = 0, "At ADP", IF(AND(H16 > 0, H16 <= 0.15), "Slightly Undervalued", IF(AND(H16 > 0.15, H16 <= 0.5), "Pretty Undervalued", IF(AND(H16 > 0.5, H16 <= 1), "Extremely Undervalued", ""))))))) -> Pretty Overvalued | J16: =IF(W16=$G$1,"M",IF(AND(U16="Drafted",W16<>$G$1),"Y","")) -> Y | K16: =IF(E16="QB",1,IF(E16="RB",2,IF(E16="WR",3,IF(E16="TE",4,IF(E16="K",5,"Check"))))) -> 2 | L16: =IF(J16="M",COUNTIFS($J$4:J16,"M",$E$4:E16,E16)&" - "&K16,"N/A") -> N/A | M16: =IFERROR(INDEX(PlayerSummaryTable[Rushing Yds],MATCH('Rankings Master'!D16,PlayerSummaryTable[Player],0)),"") -> 974.5 | N16: =IFERROR(INDEX(PlayerSummaryTable[Receiving Yds],MATCH('Rankings Master'!D16,PlayerSummaryTable[Player],0)),"") -> N/A | O16: =IFERROR(INDEX(PlayerSummaryTable[Passing Yds],MATCH('Rankings Master'!D16,PlayerSummaryTable[Player],0)),"") -> N/A | Q16: ="4 - 3" -> 4 - 3 | R16: WR4 | S16: =IFERROR(INDEX($D$4:$D$198,MATCH(Q16,$L$4:$L$198,0)),"") -> Carnell Tate | U16: =IF(COUNTIF('Draft Log'!$B$2:$B$301,D16)>0,"DRAFTED","") -> DRAFTED | V16: =IFERROR(INDEX('Draft Log'!$A$2:$A$301,MATCH(D16,'Draft Log'!$B$2:$B$301,0)),"") -> 14 | W16: =IFERROR(INDEX('Draft Log'!$C$2:$C$301,MATCH(D16,'Draft Log'!$B$2:$B$301,0)),"") -> Eight Bell Tolls
A17: 14 | B17: Jahmyr | C17: Gibbs | D17: =IF($D$1="ESPN",INDEX(Table2[Mapped Name],MATCH('Rankings Master'!$A17,Table2[Overall Rank],0)),IF('Rankings Master'!$D$1="NFL.com",INDEX(Table3[Name Clean],MATCH('Rankings Master'!$A17,Table3[Rank],0)),IF('Rankings Master'!$D$1="Sleeper",INDEX(Sleeper!$B$2:$B$201,MATCH('Rankings Master'!$A17,Sleeper!$A$2:$A$201,0)),"Need platform"))) -> Drake London | E17: =IF($D$1="ESPN",INDEX(Table2[Position],MATCH('Rankings Master'!$A17,Table2[Overall Rank],0)),IF('Rankings Master'!$D$1="NFL.com",INDEX(Table3[Position],MATCH('Rankings Master'!$A17,Table3[Rank],0)),INDEX(Sleeper!$C$2:$C$201,MATCH('Rankings Master'!A17,Sleeper!$A$2:$A$201,0)))) -> WR | F17: =INDEX(Table4[RK],MATCH('Rankings Master'!D17,Table4[PLAYER NAME],0)) -> 17 | G17: =A17-F17 -> -3 | H17: =G17/F17 -> -0.17647059 | I17: =IF(AND(H17 > -1, H17 <= -0.5), "Extremely Overvalued", IF(AND(H17 > -0.5, H17 <= -0.15), "Pretty Overvalued", IF(AND(H17 > -0.15, H17 < 0), "Slightly Overvalued", IF(H17 = 0, "At ADP", IF(AND(H17 > 0, H17 <= 0.15), "Slightly Undervalued", IF(AND(H17 > 0.15, H17 <= 0.5), "Pretty Undervalued", IF(AND(H17 > 0.5, H17 <= 1), "Extremely Undervalued", ""))))))) -> Pretty Overvalued | J17: =IF(W17=$G$1,"M",IF(AND(U17="Drafted",W17<>$G$1),"Y","")) -> Y | K17: =IF(E17="QB",1,IF(E17="RB",2,IF(E17="WR",3,IF(E17="TE",4,IF(E17="K",5,"Check"))))) -> 3 | L17: =IF(J17="M",COUNTIFS($J$4:J17,"M",$E$4:E17,E17)&" - "&K17,"N/A") -> N/A | M17: =IFERROR(INDEX(PlayerSummaryTable[Rushing Yds],MATCH('Rankings Master'!D17,PlayerSummaryTable[Player],0)),"") -> N/A | N17: =IFERROR(INDEX(PlayerSummaryTable[Receiving Yds],MATCH('Rankings Master'!D17,PlayerSummaryTable[Player],0)),"") -> 1099.5 | O17: =IFERROR(INDEX(PlayerSummaryTable[Passing Yds],MATCH('Rankings Master'!D17,PlayerSummaryTable[Player],0)),"") -> N/A | Q17: ="5 - 3" -> 5 - 3 | R17: WR5 | S17: =IFERROR(INDEX($D$4:$D$198,MATCH(Q17,$L$4:$L$198,0)),"") -> Mike Evans | U17: =IF(COUNTIF('Draft Log'!$B$2:$B$301,D17)>0,"DRAFTED","") -> DRAFTED | V17: =IFERROR(INDEX('Draft Log'!$A$2:$A$301,MATCH(D17,'Draft Log'!$B$2:$B$301,0)),"") -> 19 | W17: =IFERROR(INDEX('Draft Log'!$C$2:$C$301,MATCH(D17,'Draft Log'!$B$2:$B$301,0)),"") -> Benjamins Bandits
A18: 15 | B18: Marvin | C18: Harrison Jr. | D18: =IF($D$1="ESPN",INDEX(Table2[Mapped Name],MATCH('Rankings Master'!$A18,Table2[Overall Rank],0)),IF('Rankings Master'!$D$1="NFL.com",INDEX(Table3[Name Clean],MATCH('Rankings Master'!$A18,Table3[Rank],0)),IF('Rankings Master'!$D$1="Sleeper",INDEX(Sleeper!$B$2:$B$201,MATCH('Rankings Master'!$A18,Sleeper!$A$2:$A$201,0)),"Need platform"))) -> Saquon Barkley | E18: =IF($D$1="ESPN",INDEX(Table2[Position],MATCH('Rankings Master'!$A18,Table2[Overall Rank],0)),IF('Rankings Master'!$D$1="NFL.com",INDEX(Table3[Position],MATCH('Rankings Master'!$A18,Table3[Rank],0)),INDEX(Sleeper!$C$2:$C$201,MATCH('Rankings Master'!A18,Sleeper!$A$2:$A$201,0)))) -> RB | F18: =INDEX(Table4[RK],MATCH('Rankings Master'!D18,Table4[PLAYER NAME],0)) -> 15 | G18: =A18-F18 -> 0 | H18: =G18/F18 -> 0 | I18: =IF(AND(H18 > -1, H18 <= -0.5), "Extremely Overvalued", IF(AND(H18 > -0.5, H18 <= -0.15), "Pretty Overvalued", IF(AND(H18 > -0.15, H18 < 0), "Slightly Overvalued", IF(H18 = 0, "At ADP", IF(AND(H18 > 0, H18 <= 0.15), "Slightly Undervalued", IF(AND(H18 > 0.15, H18 <= 0.5), "Pretty Undervalued", IF(AND(H18 > 0.5, H18 <= 1), "Extremely Undervalued", ""))))))) -> At ADP | J18: =IF(W18=$G$1,"M",IF(AND(U18="Drafted",W18<>$G$1),"Y","")) -> Y | K18: =IF(E18="QB",1,IF(E18="RB",2,IF(E18="WR",3,IF(E18="TE",4,IF(E18="K",5,"Check"))))) -> 2 | L18: =IF(J18="M",COUNTIFS($J$4:J18,"M",$E$4:E18,E18)&" - "&K18,"N/A") -> N/A | M18: =IFERROR(INDEX(PlayerSummaryTable[Rushing Yds],MATCH('Rankings Master'!D18,PlayerSummaryTable[Player],0)),"") -> 1099.5 | N18: =IFERROR(INDEX(PlayerSummaryTable[Receiving Yds],MATCH('Rankings Master'!D18,PlayerSummaryTable[Player],0)),"") -> N/A | O18: =IFERROR(INDEX(PlayerSummaryTable[Passing Yds],MATCH('Rankings Master'!D18,PlayerSummaryTable[Player],0)),"") -> N/A | Q18: ="6 - 4" -> 6 - 4 | R18: WR6 | S18: =IFERROR(INDEX($D$4:$D$198,MATCH(Q18,$L$4:$L$198,0)),"") | U18: =IF(COUNTIF('Draft Log'!$B$2:$B$301,D18)>0,"DRAFTED","") -> DRAFTED | V18: =IFERROR(INDEX('Draft Log'!$A$2:$A$301,MATCH(D18,'Draft Log'!$B$2:$B$301,0)),"") -> 15 | W18: =IFERROR(INDEX('Draft Log'!$C$2:$C$301,MATCH(D18,'Draft Log'!$B$2:$B$301,0)),"") -> BEST COUNTRY IN THE WORLD
A19: 16 | B19: Drake | C19: London | D19: =IF($D$1="ESPN",INDEX(Table2[Mapped Name],MATCH('Rankings Master'!$A19,Table2[Overall Rank],0)),IF('Rankings Master'!$D$1="NFL.com",INDEX(Table3[Name Clean],MATCH('Rankings Master'!$A19,Table3[Rank],0)),IF('Rankings Master'!$D$1="Sleeper",INDEX(Sleeper!$B$2:$B$201,MATCH('Rankings Master'!$A19,Sleeper!$A$2:$A$201,0)),"Need platform"))) -> Ashton Jeanty | E19: =IF($D$1="ESPN",INDEX(Table2[Position],MATCH('Rankings Master'!$A19,Table2[Overall Rank],0)),IF('Rankings Master'!$D$1="NFL.com",INDEX(Table3[Position],MATCH('Rankings Master'!$A19,Table3[Rank],0)),INDEX(Sleeper!$C$2:$C$201,MATCH('Rankings Master'!A19,Sleeper!$A$2:$A$201,0)))) -> RB | F19: =INDEX(Table4[RK],MATCH('Rankings Master'!D19,Table4[PLAYER NAME],0)) -> 31 | G19: =A19-F19 -> -15 | H19: =G19/F19 -> -0.48387097 | I19: =IF(AND(H19 > -1, H19 <= -0.5), "Extremely Overvalued", IF(AND(H19 > -0.5, H19 <= -0.15), "Pretty Overvalued", IF(AND(H19 > -0.15, H19 < 0), "Slightly Overvalued", IF(H19 = 0, "At ADP", IF(AND(H19 > 0, H19 <= 0.15), "Slightly Undervalued", IF(AND(H19 > 0.15, H19 <= 0.5), "Pretty Undervalued", IF(AND(H19 > 0.5, H19 <= 1), "Extremely Undervalued", ""))))))) -> Pretty Overvalued | J19: =IF(W19=$G$1,"M",IF(AND(U19="Drafted",W19<>$G$1),"Y","")) -> Y | K19: =IF(E19="QB",1,IF(E19="RB",2,IF(E19="WR",3,IF(E19="TE",4,IF(E19="K",5,"Check"))))) -> 2 | L19: =IF(J19="M",COUNTIFS($J$4:J19,"M",$E$4:E19,E19)&" - "&K19,"N/A") -> N/A | M19: =IFERROR(INDEX(PlayerSummaryTable[Rushing Yds],MATCH('Rankings Master'!D19,PlayerSummaryTable[Player],0)),"") -> 1024.5 | N19: =IFERROR(INDEX(PlayerSummaryTable[Receiving Yds],MATCH('Rankings Master'!D19,PlayerSummaryTable[Player],0)),"") -> N/A | O19: =IFERROR(INDEX(PlayerSummaryTable[Passing Yds],MATCH('Rankings Master'!D19,PlayerSummaryTable[Player],0)),"") -> N/A | Q19: ="1 - 4" -> 1 - 4 | R19: TE1 | S19: =IFERROR(INDEX($D$4:$D$198,MATCH(Q19,$L$4:$L$198,0)),"") -> Brock Bowers | U19: =IF(COUNTIF('Draft Log'!$B$2:$B$301,D19)>0,"DRAFTED","") -> DRAFTED | V19: =IFERROR(INDEX('Draft Log'!$A$2:$A$301,MATCH(D19,'Draft Log'!$B$2:$B$301,0)),"") -> 18 | W19: =IFERROR(INDEX('Draft Log'!$C$2:$C$301,MATCH(D19,'Draft Log'!$B$2:$B$301,0)),"") -> dontsaynosayYA
A20: 17 | B20: Davante | C20: Adams | D20: =IF($D$1="ESPN",INDEX(Table2[Mapped Name],MATCH('Rankings Master'!$A20,Table2[Overall Rank],0)),IF('Rankings Master'!$D$1="NFL.com",INDEX(Table3[Name Clean],MATCH('Rankings Master'!$A20,Table3[Rank],0)),IF('Rankings Master'!$D$1="Sleeper",INDEX(Sleeper!$B$2:$B$201,MATCH('Rankings Master'!$A20,Sleeper!$A$2:$A$201,0)),"Need platform"))) -> Jeremiyah Love | E20: =IF($D$1="ESPN",INDEX(Table2[Position],MATCH('Rankings Master'!$A20,Table2[Overall Rank],0)),IF('Rankings Master'!$D$1="NFL.com",INDEX(Table3[Position],MATCH('Rankings Master'!$A20,Table3[Rank],0)),INDEX(Sleeper!$C$2:$C$201,MATCH('Rankings Master'!A20,Sleeper!$A$2:$A$201,0)))) -> RB | F20: =INDEX(Table4[RK],MATCH('Rankings Master'!D20,Table4[PLAYER NAME],0)) -> 44 | G20: =A20-F20 -> -27 | H20: =G20/F20 -> -0.61363636 | I20: =IF(AND(H20 > -1, H20 <= -0.5), "Extremely Overvalued", IF(AND(H20 > -0.5, H20 <= -0.15), "Pretty Overvalued", IF(AND(H20 > -0.15, H20 < 0), "Slightly Overvalued", IF(H20 = 0, "At ADP", IF(AND(H20 > 0, H20 <= 0.15), "Slightly Undervalued", IF(AND(H20 > 0.15, H20 <= 0.5), "Pretty Undervalued", IF(AND(H20 > 0.5, H20 <= 1), "Extremely Undervalued", ""))))))) -> Extremely Overvalued | J20: =IF(W20=$G$1,"M",IF(AND(U20="Drafted",W20<>$G$1),"Y","")) -> Y | K20: =IF(E20="QB",1,IF(E20="RB",2,IF(E20="WR",3,IF(E20="TE",4,IF(E20="K",5,"Check"))))) -> 2 | L20: =IF(J20="M",COUNTIFS($J$4:J20,"M",$E$4:E20,E20)&" - "&K20,"N/A") -> N/A | M20: =IFERROR(INDEX(PlayerSummaryTable[Rushing Yds],MATCH('Rankings Master'!D20,PlayerSummaryTable[Player],0)),"") -> 774.5 | N20: =IFERROR(INDEX(PlayerSummaryTable[Receiving Yds],MATCH('Rankings Master'!D20,PlayerSummaryTable[Player],0)),"") -> N/A | O20: =IFERROR(INDEX(PlayerSummaryTable[Passing Yds],MATCH('Rankings Master'!D20,PlayerSummaryTable[Player],0)),"") -> N/A | Q20: ="2 - 4" -> 2 - 4 | R20: TE2 | S20: =IFERROR(INDEX($D$4:$D$198,MATCH(Q20,$L$4:$L$198,0)),"") | U20: =IF(COUNTIF('Draft Log'!$B$2:$B$301,D20)>0,"DRAFTED","") -> DRAFTED | V20: =IFERROR(INDEX('Draft Log'!$A$2:$A$301,MATCH(D20,'Draft Log'!$B$2:$B$301,0)),"") -> 22 | W20: =IFERROR(INDEX('Draft Log'!$C$2:$C$301,MATCH(D20,'Draft Log'!$B$2:$B$301,0)),"") -> Benjamins Bandits
